Workbook
Name Product_Portfolio: #REF!

Sheet How to Use
B2: Please find below the instruction on how to run the RCCP
B3: The RCCP consists out of 11 sheets:
A6: 1 | B6: Demand Plan
B7: In the Demand Plan the plan (forecast) from demand planning can be loaded. The format needs to to be horizontally loaded. So in Column E month 1 the demand plan per SKU/Aggregation level is entered, Column F month 2 demand plan is loaded etc.
B8: Critical columns here are: 1) BU, 2) plant, 3) Material, and 4) Technology (only applicable in case of RCCP on product channel/technology level). Moreover, it is important that the top row contains the month number in format DD/MM/YYYY. In order to run this version of the RCCP these columns should at least be populated.
A10: 2 | B10: RCCP Conversion
B11: The RCCP Conversion sheet converts the data from the demand plan into the correct and usable format to be used for the RCCP. This is all done by formulas. The main action that has to be done for this sheet is to make sure that GREEN colored cells have the Site (as in column B sheet demand plan) and, if applicable, the technology families/product channels (as in Column D sheet Demand Plan)
B13: Please make sure that the formulas in row 6 and below are dragged down to the final technology family/product channel entered
A15: 3 | B15: Input Capability Review
B16: In the sheet Input capability the capacities related to the site/technology families/product channels can be found
B17: The information here is coming from manufacturing. In this sheet we find per site/technology family/product channels the following two capacities
B18: 1) Available demonstrated capacity: The available demonstrated capacity is the MAC * the available units/time. This means that the Available demonstrated capacity is the maximum achievable capacity of production given the time available (e.g 1/2/3 shifts)
B20: 2) Planned available demonstrated capacity: The planned available demonstrated capacity is a percentage of the available demonstrated capacity. Since the MAC is the maximum achievable capacity we potentially might not want to plan on this capacity. The MAC is only reached by production 25% of the times, hence in 75% they are lower than the MAC. In order to take this deviation into account a percentage of the Available demonstrated capacity can be taken. The planned available demonstrated capacity can never be higher than the available demonstrated capacity
B22: The percentage that we choose to take over the available demonstrated capacity can be indicated in Column D
B38: The above table illustrates the two types of capacity for each of the months. In this example we take 80% of the available demonstrated capacity as our planning target. This 80% is then applied to all 36 months
B40: The table needs to be copied per site/technology family/product channel.. In case there are 5 product channels, the table needs to be copied 6 times. Once for the site and 1 for each of the channels
B43: NB: When setting the RCCP for a new month, please make sure that the capacities are updated/moved to the right month so that when the first month is June instead of May, the capacities of June are in the right colum (this goes for all months). The table does not automatically move the capacities when setting the RCCP and all sheets to the new month
A45: 4 | B45: RCCP
B46: In the RCCP sheet the information of the Demand Plan sheet and the Input Capability review sheet is combined into one overview per site/Technology family/product channel
B48: When setting up the RCCP please update the current month and year to reflect the starting month of the RCCP. For example, in the June cycle the starting month needs to be set to June etc.
B53: Per site/Technology Family/Product channel there will be one table as will be explained below.
B55: 1) Demand Plan (Formula-automatic): this is the input directly imported from the Demand Plan sheet and allocated to the correct month.
B56: 2) Demand Intermediates(Formula- markup is manual): In case demand for intermediate production is not included in the Demand Plan but is relevant for the site or a certain technology family/channel, a percentage can be entered in the column Standard markup value. This percentage will be applied to all months. For example, if on average (historical data) 10% of the volume is intermediate demand, the standard markup value is 10%. This also needs to be mentioned in the sheet Assumptions
B58: 3) MTO Demand Plan(Formula- markup is manual): In case MTOs are not in the Demand Plan but this is relevaant for the site or a certain technology family/product channel, a percentage can be entered in the column Standard markup value. This percentage will be applied to all months. For example, if on average (historical data) 20% of the volume is MTO, the standard markup value is 10%. This also needs to be mentioned in the sheet Assumptions
B60: 4) Demand Plan Total Gross (Formula- Automatic): Sum of the Demand Plan including the mark ups for MTO & Intermediates
B61: 5) ICD demand plan (Formula - markup is manual): In case ICD requirements are not included in the Demand Plan for the site or a certain technology family/production channel, a percentage can be entered in the column Standard Markup value. This percentage will be applied to all months. For example, if on average (historical data) 5% of the volume is ICD related, the standard markup value is 2%. his also needs to be mentioned in the sheet Assumptions
B62: 6) Demand Plan Total Net (Formula-Automatic): Sum of the Demand Plan total gross and the ICD requirements. This is also the volume on which the capacity utilization will be based
B82: Next, 3 types of input can also be included in the Total Net Demand Plan. These are all manual inputs.
B83: 1) Toll manufacture: This is volume that is being tolled (produced by a 3rd party) or that a site is tolling for a 3rd party and that is not included in the Demand Plan
B84: 2) Transfer Volume: This is volume that is transferred to the site(or family/product channel) or that is transferred from the site (or family/product channel) to another site within AkzoNobel and is not yet included in the Demand Plan
... B140: Finally, in order to import the correct Demand Plan data for the site/family/product channel the name in the yellow column needs to be set equal to the name of the site/technology family/product channel in the sheet Demand Plan
F143: ==>
A147: 5 | B147: Capacity graphs
B148: This sheet includes the capacity graphs for the full 36 months for the site and each of the technology families/product channels set up in the RCCP sheet. In case a new family/channel is added a graph can be set up by simply copying a graph of another technology family/product channel and link it to the corresponding RCCP table
B164: Finally the following sheets can be updated with relevant information for the hub consolidation/SMR:
A165: 6 | B165: Gaps Closing: Includes the gaps there currently are in the RCCP for a site and the proposed actions/alternatives
A166: 7 | B166: Assumptions: Overview of all assumptions that are taken in the RCCP (for example the MTO Demand Plan mark up) including a timeline on how we think the assumption will progress over time. For example, there is an action to include MTO in the Demand Plan so we estimate that the assumption of 20% mark up will decrease to only 5% in 6 months time and 0% in 12 months time
A168: 8/9 | B168: Opportunities and Vulnerabilites: Overview of the Opportunities we see (e.g capex to expand machinery, extra manning, extra shift, CI initiatives), and vulnerabilities (e.g. strike, machinery breakdown due to low maintenance in the past)
A169: 10 | B169: Summary: Overview the bottleneck, the gap and the recommend gap closing actions

Sheet Demand Plan
A1: Category | B1: Factory | C1: Material | D1: Product category | E1: Customer | F1: 44713 | G1: 44743 | H1: 44774 | I1: 44805 | J1: 44835 | K1: 44866 | L1: 44896 | M1: 44927 | N1: 44958 | O1: 44986 | P1: 45017 | Q1: 45047 | R1: 45078 | S1: 45108 | T1: 45139 | U1: 45170 | V1: 45200 | W1: 45231 | X1: 45261 | Y1: 45292 | Z1: 45323 | AA1: 45352 | AB1: 45383 | AC1: 45413 | AD1: 45444 | AE1: 45474 | AF1: 45505 | AG1: 45536 | AH1: 45566 | AI1: 45597 | AJ1: 45627 | AK1: 45658 | AL1: 45689 | AM1: 45717 | AN1: 45748 | AO1: 45778
F2: 44713 | G2: 43282 | H2: 43313 | I2: 43344 | J2: 43374 | K2: 43405 | L2: 43435 | M2: 43466 | N2: 43497 | O2: 43525 | P2: 43556 | Q2: 43586 | R2: 43617 | S2: 43647 | T2: 43678 | U2: 43709 | V2: 43739 | W2: 43770 | X2: 43800 | Y2: 43831 | Z2: 43862 | AA2: 43891 | AB2: 43922 | AC2: 43952 | AD2: 43983 | AE2: 44013 | AF2: 44044 | AG2: 44075 | AH2: 44105 | AI2: 44136 | AJ2: 44166 | AK2: 44197 | AL2: 44228 | AM2: 44256 | AN2: 44287 | AO2: 44317

Sheet RCCP Conversion
B2: Year/Month Text | C2: =LEFT(C4,4)&C3 -> 2022Jun | D2: =LEFT(D4,4)&D3 -> 2018Jul | E2: =LEFT(E4,4)&E3 -> 2018Aug | F2: =LEFT(F4,4)&F3 -> 2018Sep | G2: =LEFT(G4,4)&G3 -> 2018Oct | H2: =LEFT(H4,4)&H3 -> 2018Nov | I2: =LEFT(I4,4)&I3 -> 2018Dec | J2: =LEFT(J4,4)&J3 -> 2019Jan | ... AL2: =LEFT(AL4,4)&AL3 -> 2021May
B3: Month Text | C3: =VLOOKUP(RIGHT(C4,2),'Dates conversion sheet'!$B:$C,2,0) -> Jun | D3: =VLOOKUP(RIGHT(D4,2),'Dates conversion sheet'!$B:$C,2,0) -> Jul | E3: =VLOOKUP(RIGHT(E4,2),'Dates conversion sheet'!$B:$C,2,0) -> Aug | F3: =VLOOKUP(RIGHT(F4,2),'Dates conversion sheet'!$B:$C,2,0) -> Sep | G3: =VLOOKUP(RIGHT(G4,2),'Dates conversion sheet'!$B:$C,2,0) -> Oct | H3: =VLOOKUP(RIGHT(H4,2),'Dates conversion sheet'!$B:$C,2,0) -> Nov | I3: =VLOOKUP(RIGHT(I4,2),'Dates conversion sheet'!$B:$C,2,0) -> Dec | J3: =VLOOKUP(RIGHT(J4,2),'Dates conversion sheet'!$B:$C,2,0) -> Jan | ... AL3: =VLOOKUP(RIGHT(AL4,2),'Dates conversion sheet'!$B:$C,2,0) -> May
B4: Year/Month | C4: =IF(MONTH('Demand Plan'!F2)<10,YEAR('Demand Plan'!F2)&"0"&MONTH('Demand Plan'!F2),YEAR('Demand Plan'!F2)&MONTH('Demand Plan'!F2)) -> 202206 | D4: =IF(MONTH('Demand Plan'!G2)<10,YEAR('Demand Plan'!G2)&"0"&MONTH('Demand Plan'!G2),YEAR('Demand Plan'!G2)&MONTH('Demand Plan'!G2)) -> 201807 | E4: =IF(MONTH('Demand Plan'!H2)<10,YEAR('Demand Plan'!H2)&"0"&MONTH('Demand Plan'!H2),YEAR('Demand Plan'!H2)&MONTH('Demand Plan'!H2)) -> 201808 | F4: =IF(MONTH('Demand Plan'!I2)<10,YEAR('Demand Plan'!I2)&"0"&MONTH('Demand Plan'!I2),YEAR('Demand Plan'!I2)&MONTH('Demand Plan'!I2)) -> 201809 | G4: =IF(MONTH('Demand Plan'!J2)<10,YEAR('Demand Plan'!J2)&"0"&MONTH('Demand Plan'!J2),YEAR('Demand Plan'!J2)&MONTH('Demand Plan'!J2)) -> 201810 | H4: =IF(MONTH('Demand Plan'!K2)<10,YEAR('Demand Plan'!K2)&"0"&MONTH('Demand Plan'!K2),YEAR('Demand Plan'!K2)&MONTH('Demand Plan'!K2)) -> 201811 | I4: =IF(MONTH('Demand Plan'!L2)<10,YEAR('Demand Plan'!L2)&"0"&MONTH('Demand Plan'!L2),YEAR('Demand Plan'!L2)&MONTH('Demand Plan'!L2)) -> 201812 | J4: =IF(MONTH('Demand Plan'!M2)<10,YEAR('Demand Plan'!M2)&"0"&MONTH('Demand Plan'!M2),YEAR('Demand Plan'!M2)&MONTH('Demand Plan'!M2)) -> 201901 | ... AL4: =IF(MONTH('Demand Plan'!AO2)<10,YEAR('Demand Plan'!AO2)&"0"&MONTH('Demand Plan'!AO2),YEAR('Demand Plan'!AO2)&MONTH('Demand Plan'!AO2)) -> 202105
B5: Year/Week | C5: =IF(WEEKNUM('Demand Plan'!F2,21)<10,YEAR('Demand Plan'!F2)&"0"&WEEKNUM('Demand Plan'!F2,21),YEAR('Demand Plan'!F2)&WEEKNUM('Demand Plan'!F2,21)) -> 202222 | D5: =IF(WEEKNUM('Demand Plan'!G2,21)<10,YEAR('Demand Plan'!G2)&"0"&WEEKNUM('Demand Plan'!G2,21),YEAR('Demand Plan'!G2)&WEEKNUM('Demand Plan'!G2,21)) -> 201826 | E5: =IF(WEEKNUM('Demand Plan'!H2,21)<10,YEAR('Demand Plan'!H2)&"0"&WEEKNUM('Demand Plan'!H2,21),YEAR('Demand Plan'!H2)&WEEKNUM('Demand Plan'!H2,21)) -> 201831 | F5: =IF(WEEKNUM('Demand Plan'!I2,21)<10,YEAR('Demand Plan'!I2)&"0"&WEEKNUM('Demand Plan'!I2,21),YEAR('Demand Plan'!I2)&WEEKNUM('Demand Plan'!I2,21)) -> 201835 | G5: =IF(WEEKNUM('Demand Plan'!J2,21)<10,YEAR('Demand Plan'!J2)&"0"&WEEKNUM('Demand Plan'!J2,21),YEAR('Demand Plan'!J2)&WEEKNUM('Demand Plan'!J2,21)) -> 201840 | H5: =IF(WEEKNUM('Demand Plan'!K2,21)<10,YEAR('Demand Plan'!K2)&"0"&WEEKNUM('Demand Plan'!K2,21),YEAR('Demand Plan'!K2)&WEEKNUM('Demand Plan'!K2,21)) -> 201844 | I5: =IF(WEEKNUM('Demand Plan'!L2,21)<10,YEAR('Demand Plan'!L2)&"0"&WEEKNUM('Demand Plan'!L2,21),YEAR('Demand Plan'!L2)&WEEKNUM('Demand Plan'!L2,21)) -> 201848 | J5: =IF(WEEKNUM('Demand Plan'!M2,21)<10,YEAR('Demand Plan'!M2)&"0"&WEEKNUM('Demand Plan'!M2,21),YEAR('Demand Plan'!M2)&WEEKNUM('Demand Plan'!M2,21)) -> 201901 | ... AL5: =IF(WEEKNUM('Demand Plan'!AO2,21)<10,YEAR('Demand Plan'!AO2)&"0"&WEEKNUM('Demand Plan'!AO2,21),YEAR('Demand Plan'!AO2)&WEEKNUM('Demand Plan'!AO2,21)) -> 202117
B6: HIPT | C6: =SUMIF('Demand Plan'!$B$3:$B$99669,'RCCP Conversion'!$B6,'Demand Plan'!F$3:F$99669) -> 0 | D6: =SUMIF('Demand Plan'!$B$3:$B$99669,'RCCP Conversion'!$B6,'Demand Plan'!G$3:G$99669) -> 0 | E6: =SUMIF('Demand Plan'!$B$3:$B$99669,'RCCP Conversion'!$B6,'Demand Plan'!H$3:H$99669) -> 0 | F6: =SUMIF('Demand Plan'!$B$3:$B$99669,'RCCP Conversion'!$B6,'Demand Plan'!I$3:I$99669) -> 0 | G6: =SUMIF('Demand Plan'!$B$3:$B$99669,'RCCP Conversion'!$B6,'Demand Plan'!J$3:J$99669) -> 0 | H6: =SUMIF('Demand Plan'!$B$3:$B$99669,'RCCP Conversion'!$B6,'Demand Plan'!K$3:K$99669) -> 0 | I6: =SUMIF('Demand Plan'!$B$3:$B$99669,'RCCP Conversion'!$B6,'Demand Plan'!L$3:L$99669) -> 0 | J6: =SUMIF('Demand Plan'!$B$3:$B$99669,'RCCP Conversion'!$B6,'Demand Plan'!M$3:M$99669) -> 0 | ... AL6: =SUMIF('Demand Plan'!$B$3:$B$99669,'RCCP Conversion'!$B6,'Demand Plan'!AO$3:AO$99669) -> 0
B7: Lacquer | C7: =SUMIF('Demand Plan'!$E$3:$E$99669,'RCCP Conversion'!$B7,'Demand Plan'!F$3:F$99669) -> 0 | D7: =SUMIF('Demand Plan'!$E$3:$E$99669,'RCCP Conversion'!$B7,'Demand Plan'!G$3:G$99669) -> 0 | E7: =SUMIF('Demand Plan'!$E$3:$E$99669,'RCCP Conversion'!$B7,'Demand Plan'!H$3:H$99669) -> 0 | F7: =SUMIF('Demand Plan'!$E$3:$E$99669,'RCCP Conversion'!$B7,'Demand Plan'!I$3:I$99669) -> 0 | G7: =SUMIF('Demand Plan'!$E$3:$E$99669,'RCCP Conversion'!$B7,'Demand Plan'!J$3:J$99669) -> 0 | H7: =SUMIF('Demand Plan'!$E$3:$E$99669,'RCCP Conversion'!$B7,'Demand Plan'!K$3:K$99669) -> 0 | I7: =SUMIF('Demand Plan'!$E$3:$E$99669,'RCCP Conversion'!$B7,'Demand Plan'!L$3:L$99669) -> 0 | J7: =SUMIF('Demand Plan'!$E$3:$E$99669,'RCCP Conversion'!$B7,'Demand Plan'!M$3:M$99669) -> 0 | ... AL7: =SUMIF('Demand Plan'!$E$3:$E$99669,'RCCP Conversion'!$B7,'Demand Plan'!AO$3:AO$99669) -> 0
B8: Paint | C8: =SUMIF('Demand Plan'!$E$3:$E$99669,'RCCP Conversion'!$B8,'Demand Plan'!F$3:F$99669) -> 0 | D8: =SUMIF('Demand Plan'!$E$3:$E$99669,'RCCP Conversion'!$B8,'Demand Plan'!G$3:G$99669) -> 0 | E8: =SUMIF('Demand Plan'!$E$3:$E$99669,'RCCP Conversion'!$B8,'Demand Plan'!H$3:H$99669) -> 0 | F8: =SUMIF('Demand Plan'!$E$3:$E$99669,'RCCP Conversion'!$B8,'Demand Plan'!I$3:I$99669) -> 0 | G8: =SUMIF('Demand Plan'!$E$3:$E$99669,'RCCP Conversion'!$B8,'Demand Plan'!J$3:J$99669) -> 0 | H8: =SUMIF('Demand Plan'!$E$3:$E$99669,'RCCP Conversion'!$B8,'Demand Plan'!K$3:K$99669) -> 0 | I8: =SUMIF('Demand Plan'!$E$3:$E$99669,'RCCP Conversion'!$B8,'Demand Plan'!L$3:L$99669) -> 0 | J8: =SUMIF('Demand Plan'!$E$3:$E$99669,'RCCP Conversion'!$B8,'Demand Plan'!M$3:M$99669) -> 0 | ... AL8: =SUMIF('Demand Plan'!$E$3:$E$99669,'RCCP Conversion'!$B8,'Demand Plan'!AO$3:AO$99669) -> 0
B9: Stain | C9: =SUMIF('Demand Plan'!$E$3:$E$99669,'RCCP Conversion'!$B9,'Demand Plan'!F$3:F$99669) -> 0 | D9: =SUMIF('Demand Plan'!$E$3:$E$99669,'RCCP Conversion'!$B9,'Demand Plan'!G$3:G$99669) -> 0 | E9: =SUMIF('Demand Plan'!$E$3:$E$99669,'RCCP Conversion'!$B9,'Demand Plan'!H$3:H$99669) -> 0 | F9: =SUMIF('Demand Plan'!$E$3:$E$99669,'RCCP Conversion'!$B9,'Demand Plan'!I$3:I$99669) -> 0 | G9: =SUMIF('Demand Plan'!$E$3:$E$99669,'RCCP Conversion'!$B9,'Demand Plan'!J$3:J$99669) -> 0 | H9: =SUMIF('Demand Plan'!$E$3:$E$99669,'RCCP Conversion'!$B9,'Demand Plan'!K$3:K$99669) -> 0 | I9: =SUMIF('Demand Plan'!$E$3:$E$99669,'RCCP Conversion'!$B9,'Demand Plan'!L$3:L$99669) -> 0 | J9: =SUMIF('Demand Plan'!$E$3:$E$99669,'RCCP Conversion'!$B9,'Demand Plan'!M$3:M$99669) -> 0 | ... AL9: =SUMIF('Demand Plan'!$E$3:$E$99669,'RCCP Conversion'!$B9,'Demand Plan'!AO$3:AO$99669) -> 0
B10: Water | C10: =SUMIF('Demand Plan'!$E$3:$E$99669,'RCCP Conversion'!$B10,'Demand Plan'!F$3:F$99669) -> 0 | D10: =SUMIF('Demand Plan'!$E$3:$E$99669,'RCCP Conversion'!$B10,'Demand Plan'!G$3:G$99669) -> 0 | E10: =SUMIF('Demand Plan'!$E$3:$E$99669,'RCCP Conversion'!$B10,'Demand Plan'!H$3:H$99669) -> 0 | F10: =SUMIF('Demand Plan'!$E$3:$E$99669,'RCCP Conversion'!$B10,'Demand Plan'!I$3:I$99669) -> 0 | G10: =SUMIF('Demand Plan'!$E$3:$E$99669,'RCCP Conversion'!$B10,'Demand Plan'!J$3:J$99669) -> 0 | H10: =SUMIF('Demand Plan'!$E$3:$E$99669,'RCCP Conversion'!$B10,'Demand Plan'!K$3:K$99669) -> 0 | I10: =SUMIF('Demand Plan'!$E$3:$E$99669,'RCCP Conversion'!$B10,'Demand Plan'!L$3:L$99669) -> 0 | J10: =SUMIF('Demand Plan'!$E$3:$E$99669,'RCCP Conversion'!$B10,'Demand Plan'!M$3:M$99669) -> 0 | ... AL10: =SUMIF('Demand Plan'!$E$3:$E$99669,'RCCP Conversion'!$B10,'Demand Plan'!AO$3:AO$99669) -> 0
B11: UV | C11: =SUMIF('Demand Plan'!$E$3:$E$99669,'RCCP Conversion'!$B11,'Demand Plan'!F$3:F$99669) -> 0 | D11: =SUMIF('Demand Plan'!$E$3:$E$99669,'RCCP Conversion'!$B11,'Demand Plan'!G$3:G$99669) -> 0 | E11: =SUMIF('Demand Plan'!$E$3:$E$99669,'RCCP Conversion'!$B11,'Demand Plan'!H$3:H$99669) -> 0 | F11: =SUMIF('Demand Plan'!$E$3:$E$99669,'RCCP Conversion'!$B11,'Demand Plan'!I$3:I$99669) -> 0 | G11: =SUMIF('Demand Plan'!$E$3:$E$99669,'RCCP Conversion'!$B11,'Demand Plan'!J$3:J$99669) -> 0 | H11: =SUMIF('Demand Plan'!$E$3:$E$99669,'RCCP Conversion'!$B11,'Demand Plan'!K$3:K$99669) -> 0 | I11: =SUMIF('Demand Plan'!$E$3:$E$99669,'RCCP Conversion'!$B11,'Demand Plan'!L$3:L$99669) -> 0 | J11: =SUMIF('Demand Plan'!$E$3:$E$99669,'RCCP Conversion'!$B11,'Demand Plan'!M$3:M$99669) -> 0 | ... AL11: =SUMIF('Demand Plan'!$E$3:$E$99669,'RCCP Conversion'!$B11,'Demand Plan'!AO$3:AO$99669) -> 0
B12: Solutions | C12: =SUMIF('Demand Plan'!$E$3:$E$99669,'RCCP Conversion'!$B12,'Demand Plan'!F$3:F$99669) -> 0 | D12: =SUMIF('Demand Plan'!$E$3:$E$99669,'RCCP Conversion'!$B12,'Demand Plan'!G$3:G$99669) -> 0 | E12: =SUMIF('Demand Plan'!$E$3:$E$99669,'RCCP Conversion'!$B12,'Demand Plan'!H$3:H$99669) -> 0 | F12: =SUMIF('Demand Plan'!$E$3:$E$99669,'RCCP Conversion'!$B12,'Demand Plan'!I$3:I$99669) -> 0 | G12: =SUMIF('Demand Plan'!$E$3:$E$99669,'RCCP Conversion'!$B12,'Demand Plan'!J$3:J$99669) -> 0 | H12: =SUMIF('Demand Plan'!$E$3:$E$99669,'RCCP Conversion'!$B12,'Demand Plan'!K$3:K$99669) -> 0 | I12: =SUMIF('Demand Plan'!$E$3:$E$99669,'RCCP Conversion'!$B12,'Demand Plan'!L$3:L$99669) -> 0 | J12: =SUMIF('Demand Plan'!$E$3:$E$99669,'RCCP Conversion'!$B12,'Demand Plan'!M$3:M$99669) -> 0 | ... AL12: =SUMIF('Demand Plan'!$E$3:$E$99669,'RCCP Conversion'!$B12,'Demand Plan'!AO$3:AO$99669) -> 0
C13: =SUMIF('Demand Plan'!$E$3:$E$99669,'RCCP Conversion'!$B13,'Demand Plan'!F$3:F$99669) -> 0 | D13: =SUMIF('Demand Plan'!$E$3:$E$99669,'RCCP Conversion'!$B13,'Demand Plan'!G$3:G$99669) -> 0 | E13: =SUMIF('Demand Plan'!$E$3:$E$99669,'RCCP Conversion'!$B13,'Demand Plan'!H$3:H$99669) -> 0 | F13: =SUMIF('Demand Plan'!$E$3:$E$99669,'RCCP Conversion'!$B13,'Demand Plan'!I$3:I$99669) -> 0 | G13: =SUMIF('Demand Plan'!$E$3:$E$99669,'RCCP Conversion'!$B13,'Demand Plan'!J$3:J$99669) -> 0 | H13: =SUMIF('Demand Plan'!$E$3:$E$99669,'RCCP Conversion'!$B13,'Demand Plan'!K$3:K$99669) -> 0 | I13: =SUMIF('Demand Plan'!$E$3:$E$99669,'RCCP Conversion'!$B13,'Demand Plan'!L$3:L$99669) -> 0 | J13: =SUMIF('Demand Plan'!$E$3:$E$99669,'RCCP Conversion'!$B13,'Demand Plan'!M$3:M$99669) -> 0 | ... AL13: =SUMIF('Demand Plan'!$E$3:$E$99669,'RCCP Conversion'!$B13,'Demand Plan'!AO$3:AO$99669) -> 0
C14: =SUMIF('Demand Plan'!$E$3:$E$99669,'RCCP Conversion'!$B14,'Demand Plan'!F$3:F$99669) -> 0 | D14: =SUMIF('Demand Plan'!$E$3:$E$99669,'RCCP Conversion'!$B14,'Demand Plan'!G$3:G$99669) -> 0 | E14: =SUMIF('Demand Plan'!$E$3:$E$99669,'RCCP Conversion'!$B14,'Demand Plan'!H$3:H$99669) -> 0 | F14: =SUMIF('Demand Plan'!$E$3:$E$99669,'RCCP Conversion'!$B14,'Demand Plan'!I$3:I$99669) -> 0 | G14: =SUMIF('Demand Plan'!$E$3:$E$99669,'RCCP Conversion'!$B14,'Demand Plan'!J$3:J$99669) -> 0 | H14: =SUMIF('Demand Plan'!$E$3:$E$99669,'RCCP Conversion'!$B14,'Demand Plan'!K$3:K$99669) -> 0 | I14: =SUMIF('Demand Plan'!$E$3:$E$99669,'RCCP Conversion'!$B14,'Demand Plan'!L$3:L$99669) -> 0 | J14: =SUMIF('Demand Plan'!$E$3:$E$99669,'RCCP Conversion'!$B14,'Demand Plan'!M$3:M$99669) -> 0 | ... AL14: =SUMIF('Demand Plan'!$E$3:$E$99669,'RCCP Conversion'!$B14,'Demand Plan'!AO$3:AO$99669) -> 0
C15: =SUMIF('Demand Plan'!$E$3:$E$99669,'RCCP Conversion'!$B15,'Demand Plan'!F$3:F$99669) -> 0 | D15: =SUMIF('Demand Plan'!$E$3:$E$99669,'RCCP Conversion'!$B15,'Demand Plan'!G$3:G$99669) -> 0 | E15: =SUMIF('Demand Plan'!$E$3:$E$99669,'RCCP Conversion'!$B15,'Demand Plan'!H$3:H$99669) -> 0 | F15: =SUMIF('Demand Plan'!$E$3:$E$99669,'RCCP Conversion'!$B15,'Demand Plan'!I$3:I$99669) -> 0 | G15: =SUMIF('Demand Plan'!$E$3:$E$99669,'RCCP Conversion'!$B15,'Demand Plan'!J$3:J$99669) -> 0 | H15: =SUMIF('Demand Plan'!$E$3:$E$99669,'RCCP Conversion'!$B15,'Demand Plan'!K$3:K$99669) -> 0 | I15: =SUMIF('Demand Plan'!$E$3:$E$99669,'RCCP Conversion'!$B15,'Demand Plan'!L$3:L$99669) -> 0 | J15: =SUMIF('Demand Plan'!$E$3:$E$99669,'RCCP Conversion'!$B15,'Demand Plan'!M$3:M$99669) -> 0 | ... AL15: =SUMIF('Demand Plan'!$E$3:$E$99669,'RCCP Conversion'!$B15,'Demand Plan'!AO$3:AO$99669) -> 0
C16: =SUMIF('Demand Plan'!$E$3:$E$99669,'RCCP Conversion'!$B16,'Demand Plan'!F$3:F$99669) -> 0 | D16: =SUMIF('Demand Plan'!$E$3:$E$99669,'RCCP Conversion'!$B16,'Demand Plan'!G$3:G$99669) -> 0 | E16: =SUMIF('Demand Plan'!$E$3:$E$99669,'RCCP Conversion'!$B16,'Demand Plan'!H$3:H$99669) -> 0 | F16: =SUMIF('Demand Plan'!$E$3:$E$99669,'RCCP Conversion'!$B16,'Demand Plan'!I$3:I$99669) -> 0 | G16: =SUMIF('Demand Plan'!$E$3:$E$99669,'RCCP Conversion'!$B16,'Demand Plan'!J$3:J$99669) -> 0 | H16: =SUMIF('Demand Plan'!$E$3:$E$99669,'RCCP Conversion'!$B16,'Demand Plan'!K$3:K$99669) -> 0 | I16: =SUMIF('Demand Plan'!$E$3:$E$99669,'RCCP Conversion'!$B16,'Demand Plan'!L$3:L$99669) -> 0 | J16: =SUMIF('Demand Plan'!$E$3:$E$99669,'RCCP Conversion'!$B16,'Demand Plan'!M$3:M$99669) -> 0 | ... AL16: =SUMIF('Demand Plan'!$E$3:$E$99669,'RCCP Conversion'!$B16,'Demand Plan'!AO$3:AO$99669) -> 0
C17: =SUMIF('Demand Plan'!$E$3:$E$99669,'RCCP Conversion'!$B17,'Demand Plan'!F$3:F$99669) -> 0 | D17: =SUMIF('Demand Plan'!$E$3:$E$99669,'RCCP Conversion'!$B17,'Demand Plan'!G$3:G$99669) -> 0 | E17: =SUMIF('Demand Plan'!$E$3:$E$99669,'RCCP Conversion'!$B17,'Demand Plan'!H$3:H$99669) -> 0 | F17: =SUMIF('Demand Plan'!$E$3:$E$99669,'RCCP Conversion'!$B17,'Demand Plan'!I$3:I$99669) -> 0 | G17: =SUMIF('Demand Plan'!$E$3:$E$99669,'RCCP Conversion'!$B17,'Demand Plan'!J$3:J$99669) -> 0 | H17: =SUMIF('Demand Plan'!$E$3:$E$99669,'RCCP Conversion'!$B17,'Demand Plan'!K$3:K$99669) -> 0 | I17: =SUMIF('Demand Plan'!$E$3:$E$99669,'RCCP Conversion'!$B17,'Demand Plan'!L$3:L$99669) -> 0 | J17: =SUMIF('Demand Plan'!$E$3:$E$99669,'RCCP Conversion'!$B17,'Demand Plan'!M$3:M$99669) -> 0 | ... AL17: =SUMIF('Demand Plan'!$E$3:$E$99669,'RCCP Conversion'!$B17,'Demand Plan'!AO$3:AO$99669) -> 0
C18: =SUMIF('Demand Plan'!$E$3:$E$99669,'RCCP Conversion'!$B18,'Demand Plan'!F$3:F$99669) -> 0 | D18: =SUMIF('Demand Plan'!$E$3:$E$99669,'RCCP Conversion'!$B18,'Demand Plan'!G$3:G$99669) -> 0 | E18: =SUMIF('Demand Plan'!$E$3:$E$99669,'RCCP Conversion'!$B18,'Demand Plan'!H$3:H$99669) -> 0 | F18: =SUMIF('Demand Plan'!$E$3:$E$99669,'RCCP Conversion'!$B18,'Demand Plan'!I$3:I$99669) -> 0 | G18: =SUMIF('Demand Plan'!$E$3:$E$99669,'RCCP Conversion'!$B18,'Demand Plan'!J$3:J$99669) -> 0 | H18: =SUMIF('Demand Plan'!$E$3:$E$99669,'RCCP Conversion'!$B18,'Demand Plan'!K$3:K$99669) -> 0 | I18: =SUMIF('Demand Plan'!$E$3:$E$99669,'RCCP Conversion'!$B18,'Demand Plan'!L$3:L$99669) -> 0 | J18: =SUMIF('Demand Plan'!$E$3:$E$99669,'RCCP Conversion'!$B18,'Demand Plan'!M$3:M$99669) -> 0 | ... AL18: =SUMIF('Demand Plan'!$E$3:$E$99669,'RCCP Conversion'!$B18,'Demand Plan'!AO$3:AO$99669) -> 0
C19: =SUMIF('Demand Plan'!$E$3:$E$99669,'RCCP Conversion'!$B19,'Demand Plan'!F$3:F$99669) -> 0 | D19: =SUMIF('Demand Plan'!$E$3:$E$99669,'RCCP Conversion'!$B19,'Demand Plan'!G$3:G$99669) -> 0 | E19: =SUMIF('Demand Plan'!$E$3:$E$99669,'RCCP Conversion'!$B19,'Demand Plan'!H$3:H$99669) -> 0 | F19: =SUMIF('Demand Plan'!$E$3:$E$99669,'RCCP Conversion'!$B19,'Demand Plan'!I$3:I$99669) -> 0 | G19: =SUMIF('Demand Plan'!$E$3:$E$99669,'RCCP Conversion'!$B19,'Demand Plan'!J$3:J$99669) -> 0 | H19: =SUMIF('Demand Plan'!$E$3:$E$99669,'RCCP Conversion'!$B19,'Demand Plan'!K$3:K$99669) -> 0 | I19: =SUMIF('Demand Plan'!$E$3:$E$99669,'RCCP Conversion'!$B19,'Demand Plan'!L$3:L$99669) -> 0 | J19: =SUMIF('Demand Plan'!$E$3:$E$99669,'RCCP Conversion'!$B19,'Demand Plan'!M$3:M$99669) -> 0 | ... AL19: =SUMIF('Demand Plan'!$E$3:$E$99669,'RCCP Conversion'!$B19,'Demand Plan'!AO$3:AO$99669) -> 0
C20: =SUMIF('Demand Plan'!$E$3:$E$99669,'RCCP Conversion'!$B20,'Demand Plan'!F$3:F$99669) -> 0 | D20: =SUMIF('Demand Plan'!$E$3:$E$99669,'RCCP Conversion'!$B20,'Demand Plan'!G$3:G$99669) -> 0 | E20: =SUMIF('Demand Plan'!$E$3:$E$99669,'RCCP Conversion'!$B20,'Demand Plan'!H$3:H$99669) -> 0 | F20: =SUMIF('Demand Plan'!$E$3:$E$99669,'RCCP Conversion'!$B20,'Demand Plan'!I$3:I$99669) -> 0 | G20: =SUMIF('Demand Plan'!$E$3:$E$99669,'RCCP Conversion'!$B20,'Demand Plan'!J$3:J$99669) -> 0 | H20: =SUMIF('Demand Plan'!$E$3:$E$99669,'RCCP Conversion'!$B20,'Demand Plan'!K$3:K$99669) -> 0 | I20: =SUMIF('Demand Plan'!$E$3:$E$99669,'RCCP Conversion'!$B20,'Demand Plan'!L$3:L$99669) -> 0 | J20: =SUMIF('Demand Plan'!$E$3:$E$99669,'RCCP Conversion'!$B20,'Demand Plan'!M$3:M$99669) -> 0 | ... AL20: =SUMIF('Demand Plan'!$E$3:$E$99669,'RCCP Conversion'!$B20,'Demand Plan'!AO$3:AO$99669) -> 0
C21: =SUMIF('Demand Plan'!$E$3:$E$99669,'RCCP Conversion'!$B21,'Demand Plan'!F$3:F$99669) -> 0 | D21: =SUMIF('Demand Plan'!$E$3:$E$99669,'RCCP Conversion'!$B21,'Demand Plan'!G$3:G$99669) -> 0 | E21: =SUMIF('Demand Plan'!$E$3:$E$99669,'RCCP Conversion'!$B21,'Demand Plan'!H$3:H$99669) -> 0 | F21: =SUMIF('Demand Plan'!$E$3:$E$99669,'RCCP Conversion'!$B21,'Demand Plan'!I$3:I$99669) -> 0 | G21: =SUMIF('Demand Plan'!$E$3:$E$99669,'RCCP Conversion'!$B21,'Demand Plan'!J$3:J$99669) -> 0 | H21: =SUMIF('Demand Plan'!$E$3:$E$99669,'RCCP Conversion'!$B21,'Demand Plan'!K$3:K$99669) -> 0 | I21: =SUMIF('Demand Plan'!$E$3:$E$99669,'RCCP Conversion'!$B21,'Demand Plan'!L$3:L$99669) -> 0 | J21: =SUMIF('Demand Plan'!$E$3:$E$99669,'RCCP Conversion'!$B21,'Demand Plan'!M$3:M$99669) -> 0 | ... AL21: =SUMIF('Demand Plan'!$E$3:$E$99669,'RCCP Conversion'!$B21,'Demand Plan'!AO$3:AO$99669) -> 0
C22: =SUMIF('Demand Plan'!$E$3:$E$99669,'RCCP Conversion'!$B22,'Demand Plan'!F$3:F$99669) -> 0 | D22: =SUMIF('Demand Plan'!$E$3:$E$99669,'RCCP Conversion'!$B22,'Demand Plan'!G$3:G$99669) -> 0 | E22: =SUMIF('Demand Plan'!$E$3:$E$99669,'RCCP Conversion'!$B22,'Demand Plan'!H$3:H$99669) -> 0 | F22: =SUMIF('Demand Plan'!$E$3:$E$99669,'RCCP Conversion'!$B22,'Demand Plan'!I$3:I$99669) -> 0 | G22: =SUMIF('Demand Plan'!$E$3:$E$99669,'RCCP Conversion'!$B22,'Demand Plan'!J$3:J$99669) -> 0 | H22: =SUMIF('Demand Plan'!$E$3:$E$99669,'RCCP Conversion'!$B22,'Demand Plan'!K$3:K$99669) -> 0 | I22: =SUMIF('Demand Plan'!$E$3:$E$99669,'RCCP Conversion'!$B22,'Demand Plan'!L$3:L$99669) -> 0 | J22: =SUMIF('Demand Plan'!$E$3:$E$99669,'RCCP Conversion'!$B22,'Demand Plan'!M$3:M$99669) -> 0 | ... AL22: =SUMIF('Demand Plan'!$E$3:$E$99669,'RCCP Conversion'!$B22,'Demand Plan'!AO$3:AO$99669) -> 0
C23: =SUMIF('Demand Plan'!$E$3:$E$99669,'RCCP Conversion'!$B23,'Demand Plan'!F$3:F$99669) -> 0 | D23: =SUMIF('Demand Plan'!$E$3:$E$99669,'RCCP Conversion'!$B23,'Demand Plan'!G$3:G$99669) -> 0 | E23: =SUMIF('Demand Plan'!$E$3:$E$99669,'RCCP Conversion'!$B23,'Demand Plan'!H$3:H$99669) -> 0 | F23: =SUMIF('Demand Plan'!$E$3:$E$99669,'RCCP Conversion'!$B23,'Demand Plan'!I$3:I$99669) -> 0 | G23: =SUMIF('Demand Plan'!$E$3:$E$99669,'RCCP Conversion'!$B23,'Demand Plan'!J$3:J$99669) -> 0 | H23: =SUMIF('Demand Plan'!$E$3:$E$99669,'RCCP Conversion'!$B23,'Demand Plan'!K$3:K$99669) -> 0 | I23: =SUMIF('Demand Plan'!$E$3:$E$99669,'RCCP Conversion'!$B23,'Demand Plan'!L$3:L$99669) -> 0 | J23: =SUMIF('Demand Plan'!$E$3:$E$99669,'RCCP Conversion'!$B23,'Demand Plan'!M$3:M$99669) -> 0 | ... AL23: =SUMIF('Demand Plan'!$E$3:$E$99669,'RCCP Conversion'!$B23,'Demand Plan'!AO$3:AO$99669) -> 0
C24: =SUMIF('Demand Plan'!$E$3:$E$99669,'RCCP Conversion'!$B24,'Demand Plan'!F$3:F$99669) -> 0 | D24: =SUMIF('Demand Plan'!$E$3:$E$99669,'RCCP Conversion'!$B24,'Demand Plan'!G$3:G$99669) -> 0 | E24: =SUMIF('Demand Plan'!$E$3:$E$99669,'RCCP Conversion'!$B24,'Demand Plan'!H$3:H$99669) -> 0 | F24: =SUMIF('Demand Plan'!$E$3:$E$99669,'RCCP Conversion'!$B24,'Demand Plan'!I$3:I$99669) -> 0 | G24: =SUMIF('Demand Plan'!$E$3:$E$99669,'RCCP Conversion'!$B24,'Demand Plan'!J$3:J$99669) -> 0 | H24: =SUMIF('Demand Plan'!$E$3:$E$99669,'RCCP Conversion'!$B24,'Demand Plan'!K$3:K$99669) -> 0 | I24: =SUMIF('Demand Plan'!$E$3:$E$99669,'RCCP Conversion'!$B24,'Demand Plan'!L$3:L$99669) -> 0 | J24: =SUMIF('Demand Plan'!$E$3:$E$99669,'RCCP Conversion'!$B24,'Demand Plan'!M$3:M$99669) -> 0 | ... AL24: =SUMIF('Demand Plan'!$E$3:$E$99669,'RCCP Conversion'!$B24,'Demand Plan'!AO$3:AO$99669) -> 0
... C34: =SUMIF('Demand Plan'!$E$3:$E$99669,'RCCP Conversion'!$B34,'Demand Plan'!F$3:F$99669) -> 0 | D34: =SUMIF('Demand Plan'!$E$3:$E$99669,'RCCP Conversion'!$B34,'Demand Plan'!G$3:G$99669) -> 0 | E34: =SUMIF('Demand Plan'!$E$3:$E$99669,'RCCP Conversion'!$B34,'Demand Plan'!H$3:H$99669) -> 0 | F34: =SUMIF('Demand Plan'!$E$3:$E$99669,'RCCP Conversion'!$B34,'Demand Plan'!I$3:I$99669) -> 0 | G34: =SUMIF('Demand Plan'!$E$3:$E$99669,'RCCP Conversion'!$B34,'Demand Plan'!J$3:J$99669) -> 0 | H34: =SUMIF('Demand Plan'!$E$3:$E$99669,'RCCP Conversion'!$B34,'Demand Plan'!K$3:K$99669) -> 0 | I34: =SUMIF('Demand Plan'!$E$3:$E$99669,'RCCP Conversion'!$B34,'Demand Plan'!L$3:L$99669) -> 0 | J34: =SUMIF('Demand Plan'!$E$3:$E$99669,'RCCP Conversion'!$B34,'Demand Plan'!M$3:M$99669) -> 0 | ... AL34: =SUMIF('Demand Plan'!$E$3:$E$99669,'RCCP Conversion'!$B34,'Demand Plan'!AO$3:AO$99669) -> 0

Sheet Gap Closing
B2: Nr | C2: Site/Bottleneck | D2: Gap description | E2: Timing | F2: Volume Impact | G2: Cost Impact | H2: Capital Impact | I2: Resource Impact | J2: Alternative | K2: Description | L2: Volume Impact | M2: Impact
B3: 1 | J3: 1
J4: 2
J5: 3
B6: 2
B9: 3
B12: 4
B15: 5

Sheet Summary-1
B2: Equipment | C2: Nov'22 | D2: Dec'22 | E2: Jan'23
B3: EXT-1 | C3: ='RCCP Extrusion'!E20 -> 0.77546455 | D3: ='RCCP Extrusion'!F20 -> 0.7200694 | E3: ='RCCP Extrusion'!G20 -> 0.72774028
B4: EXT-2 | C4: ='RCCP Extrusion'!E38 -> 0.87892028 | D4: ='RCCP Extrusion'!F38 -> 0.61786364 | E4: ='RCCP Extrusion'!G38 -> 0.61021745
B5: EXT-3 | C5: ='RCCP Extrusion'!E56 -> 0.82257598 | D5: ='RCCP Extrusion'!F56 -> 0.68846142 | E5: ='RCCP Extrusion'!G56 -> 0.68462682
B6: EXT-4 | C6: ='RCCP Extrusion'!E74 -> 0.50246829 | D6: ='RCCP Extrusion'!F74 -> 0.34330399 | E6: ='RCCP Extrusion'!G74 -> 0.36706958
B7: EXT-5 | C7: ='RCCP Extrusion'!E92 -> 0.65219411 | D7: ='RCCP Extrusion'!F92 -> 0.46159307 | E7: ='RCCP Extrusion'!G92 -> 0.44714245
B8: EXT-6 | C8: ='RCCP Extrusion'!E110 -> 0.85632066 | D8: ='RCCP Extrusion'!F110 -> 0.6422717 | E8: ='RCCP Extrusion'!G110 -> 0.61728307
B9: EXT-10 | C9: ='RCCP Extrusion'!E128 -> 0.61467647 | D9: ='RCCP Extrusion'!F128 -> 0.56846357 | E9: ='RCCP Extrusion'!G128 -> 0.4994288
B10: EXT-11 | C10: ='RCCP Extrusion'!E146 -> 0.72338434 | D10: ='RCCP Extrusion'!F146 -> 0.51956667 | E10: ='RCCP Extrusion'!G146 -> 0.49255659
B11: EXT-12 | C11: ='RCCP Extrusion'!E164 -> 0.8587753 | D11: ='RCCP Extrusion'!F164 -> 0.81054663 | E11: ='RCCP Extrusion'!G164 -> 0.74718016
B14: Equipment | C14: Demand | D14: Capacity | E14: delta
B15: EXT-1 | C15: =SUM('RCCP Extrusion'!E16:G16) -> 1184258 | D15: =SUM('RCCP Extrusion'!E19:G19) -> 1597991.8 | E15: =ABS(D15-C15) -> 413733.81
B16: EXT-2 | C16: =SUM('RCCP Extrusion'!E34:G34) -> 1197961.7 | D16: =SUM('RCCP Extrusion'!E37:G37) -> 1705687.1 | E16: =ABS(D16-C16) -> 507725.42
B17: EXT-3 | C17: =SUM('RCCP Extrusion'!E52:G52) -> 895430.61 | D17: =SUM('RCCP Extrusion'!E55:G55) -> 1223452.9 | E17: =ABS(D17-C17) -> 328022.32
B18: EXT-4 | C18: =SUM('RCCP Extrusion'!E70:G70) -> 626719.67 | D18: =SUM('RCCP Extrusion'!E73:G73) -> 1550209.5 | E18: =ABS(D18-C18) -> 923489.87
B19: EXT-5 | C19: =SUM('RCCP Extrusion'!E88:G88) -> 738131.61 | D19: =SUM('RCCP Extrusion'!E91:G91) -> 1418638.5 | E19: =ABS(D19-C19) -> 680506.86
B20: EXT-6 | C20: =SUM('RCCP Extrusion'!E106:G106) -> 949662.44 | D20: =SUM('RCCP Extrusion'!E109:G109) -> 1346481.6 | E20: =ABS(D20-C20) -> 396819.15
B21: EXT-10 | C21: =SUM('RCCP Extrusion'!E124:G124) -> 752558.88 | D21: =SUM('RCCP Extrusion'!E127:G127) -> 1341803.4 | E21: =ABS(D21-C21) -> 589244.55
B22: EXT-11 | C22: =SUM('RCCP Extrusion'!E142:G142) -> 1035214.1 | D22: =SUM('RCCP Extrusion'!E145:G145) -> 1789472 | E22: =ABS(D22-C22) -> 754257.9
B23: EXT-12 | C23: =SUM('RCCP Extrusion'!E160:G160) -> 949416.05 | D23: =SUM('RCCP Extrusion'!E163:G163) -> 1178665.7 | E23: =ABS(D23-C23) -> 229249.66
B25: Equipment | C25: =C2 -> Nov'22 | D25: =D2 -> Dec'22 | E25: =E2 -> Jan'23
B26: Mix-1 | C26: ='RCCP Mixing'!E20 -> #DIV/0! | D26: ='RCCP Mixing'!F20 -> #DIV/0! | E26: ='RCCP Mixing'!G20 -> #DIV/0!
B27: Mix-2 | C27: ='RCCP Mixing'!E38 -> 0.98717146 | D27: ='RCCP Mixing'!F38 -> 0.85121964 | E27: ='RCCP Mixing'!G38 -> 0.69164371
B28: Mix-3 | C28: ='RCCP Mixing'!E56 -> 0.98169669 | D28: ='RCCP Mixing'!F56 -> 0.91755711 | E28: ='RCCP Mixing'!G56 -> 0.82438408
B30: Equipment | C30: Demand | D30: Capacity | E30: delta
B31: Mix-1 | C31: =SUM('RCCP Mixing'!E16:G16) -> 0 | D31: =SUM('RCCP Mixing'!E19:G19) -> 0 | E31: =ABS(D31-C31) -> 0
B32: Mix-2 | C32: =SUM('RCCP Mixing'!E34:G34) -> 970318.95 | D32: =SUM('RCCP Mixing'!E37:G37) -> 1150560 | E32: =ABS(D32-C32) -> 180241.05
B33: Mix-3 | C33: =SUM('RCCP Mixing'!E52:G52) -> 1789017.5 | D33: =SUM('RCCP Mixing'!E55:G55) -> 1970545.5 | E33: =ABS(D33-C33) -> 181528.05

Sheet Input Capability Review
B2: Site-1 | E2: ='RCCP Extrusion'!E$7 -> Nov | F2: ='RCCP Extrusion'!F$7 -> Dec | G2: ='RCCP Extrusion'!G$7 -> Jan | H2: ='RCCP Extrusion'!H$7 -> Feb | I2: ='RCCP Extrusion'!I$7 -> Mar | J2: ='RCCP Extrusion'!J$7 -> Apr | K2: ='RCCP Extrusion'!K$7 -> May | L2: ='RCCP Extrusion'!L$7 -> Jun | ... AN2: ='RCCP Extrusion'!AN$7 -> Oct
B3: Capacity | C3: Definitions | D3: % of available demonstrated capacity | E3: ='RCCP Extrusion'!E$8 -> 2022 | F3: ='RCCP Extrusion'!F$8 -> 2022 | G3: ='RCCP Extrusion'!G$8 -> 2023 | H3: ='RCCP Extrusion'!H$8 -> 2023 | I3: ='RCCP Extrusion'!I$8 -> 2023 | J3: ='RCCP Extrusion'!J$8 -> 2023 | K3: ='RCCP Extrusion'!K$8 -> 2023 | L3: ='RCCP Extrusion'!L$8 -> 2023 | ... AN3: ='RCCP Extrusion'!AN$8 -> 2025
B4: Planned available demonstrated capacity | C4: Planned available demonstrated capacity = x% of available demonstrated capacity | D4: 0.5 | E4: =E5*$D4 -> 200000 | F4: =F5*$D4 -> 200000 | G4: =G5*$D4 -> 200000 | H4: =H5*$D4 -> 200000 | I4: =I5*$D4 -> 200000 | J4: =J5*$D4 -> 200000 | K4: =K5*$D4 -> 200000 | L4: =L5*$D4 -> 200000 | ... AN4: =AN5*$D4 -> 200000
B5: Available demonstrated capacity | C5: Available demonstrated capacity = MAC * available units/time | E5: 400000 | F5: 400000 | G5: 400000 | H5: 400000 | I5: 400000 | J5: 400000 | K5: 400000 | L5: 400000 | M5: 400000 | N5: 400000 | O5: 400000 | P5: 400000 | Q5: 400000 | R5: 400000 | S5: 400000 | T5: 400000 | U5: 400000 | V5: 400000 | W5: 400000 | X5: 400000 | Y5: 400000 | Z5: 400000 | AA5: 400000 | AB5: 400000 | AC5: 400000 | AD5: 400000 | AE5: 400000 | AF5: 400000 | AG5: 400000 | AH5: 400000 | AI5: 400000 | AJ5: 400000 | AK5: 400000 | AL5: 400000 | AM5: 400000 | AN5: 400000
B7: Site-2 | E7: ='RCCP Extrusion'!E$7 -> Nov | F7: ='RCCP Extrusion'!F$7 -> Dec | G7: ='RCCP Extrusion'!G$7 -> Jan | H7: ='RCCP Extrusion'!H$7 -> Feb | I7: ='RCCP Extrusion'!I$7 -> Mar | J7: ='RCCP Extrusion'!J$7 -> Apr | K7: ='RCCP Extrusion'!K$7 -> May | L7: ='RCCP Extrusion'!L$7 -> Jun | ... AN7: ='RCCP Extrusion'!AN$7 -> Oct
B8: Capacity | C8: Definitions | D8: % of available demonstrated capacity | E8: ='RCCP Extrusion'!E$8 -> 2022 | F8: ='RCCP Extrusion'!F$8 -> 2022 | G8: ='RCCP Extrusion'!G$8 -> 2023 | H8: ='RCCP Extrusion'!H$8 -> 2023 | I8: ='RCCP Extrusion'!I$8 -> 2023 | J8: ='RCCP Extrusion'!J$8 -> 2023 | K8: ='RCCP Extrusion'!K$8 -> 2023 | L8: ='RCCP Extrusion'!L$8 -> 2023 | ... AN8: ='RCCP Extrusion'!AN$8 -> 2025
B9: Planned available demonstrated capacity | C9: Planned available demonstrated capacity = x% of available demonstrated capacity | D9: 0.75 | E9: =E10*$D9 -> 300000 | F9: =F10*$D9 -> 300000 | G9: =G10*$D9 -> 300000 | H9: =H10*$D9 -> 300000 | I9: =I10*$D9 -> 300000 | J9: =J10*$D9 -> 300000 | K9: =K10*$D9 -> 300000 | L9: =L10*$D9 -> 300000 | ... AN9: =AN10*$D9 -> 300000
B10: Available demonstrated capacity | C10: Available demonstrated capacity = MAC * available units/time | E10: 400000 | F10: 400000 | G10: 400000 | H10: 400000 | I10: 400000 | J10: 400000 | K10: 400000 | L10: 400000 | M10: 400000 | N10: 400000 | O10: 400000 | P10: 400000 | Q10: 400000 | R10: 400000 | S10: 400000 | T10: 400000 | U10: 400000 | V10: 400000 | W10: 400000 | X10: 400000 | Y10: 400000 | Z10: 400000 | AA10: 400000 | AB10: 400000 | AC10: 400000 | AD10: 400000 | AE10: 400000 | AF10: 400000 | AG10: 400000 | AH10: 400000 | AI10: 400000 | AJ10: 400000 | AK10: 400000 | AL10: 400000 | AM10: 400000 | AN10: 400000
B12: Site-3 | E12: ='RCCP Extrusion'!E$7 -> Nov | F12: ='RCCP Extrusion'!F$7 -> Dec | G12: ='RCCP Extrusion'!G$7 -> Jan | H12: ='RCCP Extrusion'!H$7 -> Feb | I12: ='RCCP Extrusion'!I$7 -> Mar | J12: ='RCCP Extrusion'!J$7 -> Apr | K12: ='RCCP Extrusion'!K$7 -> May | L12: ='RCCP Extrusion'!L$7 -> Jun | ... AN12: ='RCCP Extrusion'!AN$7 -> Oct
B13: Capacity | C13: Definitions | D13: % of available demonstrated capacity | E13: ='RCCP Extrusion'!E$8 -> 2022 | F13: ='RCCP Extrusion'!F$8 -> 2022 | G13: ='RCCP Extrusion'!G$8 -> 2023 | H13: ='RCCP Extrusion'!H$8 -> 2023 | I13: ='RCCP Extrusion'!I$8 -> 2023 | J13: ='RCCP Extrusion'!J$8 -> 2023 | K13: ='RCCP Extrusion'!K$8 -> 2023 | L13: ='RCCP Extrusion'!L$8 -> 2023 | ... AN13: ='RCCP Extrusion'!AN$8 -> 2025
B14: Planned available demonstrated capacity | C14: Planned available demonstrated capacity = x% of available demonstrated capacity | D14: 0.75 | E14: =E15*$D14 -> 300000 | F14: =F15*$D14 -> 300000 | G14: =G15*$D14 -> 300000 | H14: =H15*$D14 -> 300000 | I14: =I15*$D14 -> 300000 | J14: =J15*$D14 -> 300000 | K14: =K15*$D14 -> 300000 | L14: =L15*$D14 -> 300000 | ... AN14: =AN15*$D14 -> 300000
B15: Available demonstrated capacity | C15: Available demonstrated capacity = MAC * available units/time | E15: 400000 | F15: 400000 | G15: 400000 | H15: 400000 | I15: 400000 | J15: 400000 | K15: 400000 | L15: 400000 | M15: 400000 | N15: 400000 | O15: 400000 | P15: 400000 | Q15: 400000 | R15: 400000 | S15: 400000 | T15: 400000 | U15: 400000 | V15: 400000 | W15: 400000 | X15: 400000 | Y15: 400000 | Z15: 400000 | AA15: 400000 | AB15: 400000 | AC15: 400000 | AD15: 400000 | AE15: 400000 | AF15: 400000 | AG15: 400000 | AH15: 400000 | AI15: 400000 | AJ15: 400000 | AK15: 400000 | AL15: 400000 | AM15: 400000 | AN15: 400000
B17: Site-4 | E17: ='RCCP Extrusion'!E$7 -> Nov | F17: ='RCCP Extrusion'!F$7 -> Dec | G17: ='RCCP Extrusion'!G$7 -> Jan | H17: ='RCCP Extrusion'!H$7 -> Feb | I17: ='RCCP Extrusion'!I$7 -> Mar | J17: ='RCCP Extrusion'!J$7 -> Apr | K17: ='RCCP Extrusion'!K$7 -> May | L17: ='RCCP Extrusion'!L$7 -> Jun | ... AN17: ='RCCP Extrusion'!AN$7 -> Oct
B18: Capacity | C18: Definitions | D18: % of available demonstrated capacity | E18: ='RCCP Extrusion'!E$8 -> 2022 | F18: ='RCCP Extrusion'!F$8 -> 2022 | G18: ='RCCP Extrusion'!G$8 -> 2023 | H18: ='RCCP Extrusion'!H$8 -> 2023 | I18: ='RCCP Extrusion'!I$8 -> 2023 | J18: ='RCCP Extrusion'!J$8 -> 2023 | K18: ='RCCP Extrusion'!K$8 -> 2023 | L18: ='RCCP Extrusion'!L$8 -> 2023 | ... AN18: ='RCCP Extrusion'!AN$8 -> 2025
B19: Planned available demonstrated capacity | C19: Planned available demonstrated capacity = x% of available demonstrated capacity | D19: 0.75 | E19: =E20*$D19 -> 300000 | F19: =F20*$D19 -> 300000 | G19: =G20*$D19 -> 300000 | H19: =H20*$D19 -> 300000 | I19: =I20*$D19 -> 300000 | J19: =J20*$D19 -> 300000 | K19: =K20*$D19 -> 300000 | L19: =L20*$D19 -> 300000 | ... AN19: =AN20*$D19 -> 300000
B20: Available demonstrated capacity | C20: Available demonstrated capacity = MAC * available units/time | E20: 400000 | F20: 400000 | G20: 400000 | H20: 400000 | I20: 400000 | J20: 400000 | K20: 400000 | L20: 400000 | M20: 400000 | N20: 400000 | O20: 400000 | P20: 400000 | Q20: 400000 | R20: 400000 | S20: 400000 | T20: 400000 | U20: 400000 | V20: 400000 | W20: 400000 | X20: 400000 | Y20: 400000 | Z20: 400000 | AA20: 400000 | AB20: 400000 | AC20: 400000 | AD20: 400000 | AE20: 400000 | AF20: 400000 | AG20: 400000 | AH20: 400000 | AI20: 400000 | AJ20: 400000 | AK20: 400000 | AL20: 400000 | AM20: 400000 | AN20: 400000
B22: Site-5 | E22: ='RCCP Extrusion'!E$7 -> Nov | F22: ='RCCP Extrusion'!F$7 -> Dec | G22: ='RCCP Extrusion'!G$7 -> Jan | H22: ='RCCP Extrusion'!H$7 -> Feb | I22: ='RCCP Extrusion'!I$7 -> Mar | J22: ='RCCP Extrusion'!J$7 -> Apr | K22: ='RCCP Extrusion'!K$7 -> May | L22: ='RCCP Extrusion'!L$7 -> Jun | ... AN22: ='RCCP Extrusion'!AN$7 -> Oct
B23: Capacity | C23: Definitions | D23: % of available demonstrated capacity | E23: ='RCCP Extrusion'!E$8 -> 2022 | F23: ='RCCP Extrusion'!F$8 -> 2022 | G23: ='RCCP Extrusion'!G$8 -> 2023 | H23: ='RCCP Extrusion'!H$8 -> 2023 | I23: ='RCCP Extrusion'!I$8 -> 2023 | J23: ='RCCP Extrusion'!J$8 -> 2023 | K23: ='RCCP Extrusion'!K$8 -> 2023 | L23: ='RCCP Extrusion'!L$8 -> 2023 | ... AN23: ='RCCP Extrusion'!AN$8 -> 2025
B24: Planned available demonstrated capacity | C24: Planned available demonstrated capacity = x% of available demonstrated capacity | D24: 0.75 | E24: =E25*$D24 -> 300000 | F24: =F25*$D24 -> 300000 | G24: =G25*$D24 -> 300000 | H24: =H25*$D24 -> 300000 | I24: =I25*$D24 -> 300000 | J24: =J25*$D24 -> 300000 | K24: =K25*$D24 -> 300000 | L24: =L25*$D24 -> 300000 | ... AN24: =AN25*$D24 -> 300000
B25: Available demonstrated capacity | C25: Available demonstrated capacity = MAC * available units/time | E25: 400000 | F25: 400000 | G25: 400000 | H25: 400000 | I25: 400000 | J25: 400000 | K25: 400000 | L25: 400000 | M25: 400000 | N25: 400000 | O25: 400000 | P25: 400000 | Q25: 400000 | R25: 400000 | S25: 400000 | T25: 400000 | U25: 400000 | V25: 400000 | W25: 400000 | X25: 400000 | Y25: 400000 | Z25: 400000 | AA25: 400000 | AB25: 400000 | AC25: 400000 | AD25: 400000 | AE25: 400000 | AF25: 400000 | AG25: 400000 | AH25: 400000 | AI25: 400000 | AJ25: 400000 | AK25: 400000 | AL25: 400000 | AM25: 400000 | AN25: 400000
B27: Product category | E27: =CONCATENATE(E28,E29) -> Nov2022 | F27: =CONCATENATE(F28,F29) -> Dec2022 | G27: =CONCATENATE(G28,G29) -> Jan2023 | H27: =CONCATENATE(H28,H29) -> Feb2023 | I27: =CONCATENATE(I28,I29) -> Mar2023 | J27: =CONCATENATE(J28,J29) -> Apr2023 | K27: =CONCATENATE(K28,K29) -> May2023 | L27: =CONCATENATE(L28,L29) -> Jun2023 | ... AN27: =CONCATENATE(AN28,AN29) -> Oct2025
B28: Body mounted door seals | E28: =E$2 -> Nov | F28: =F$2 -> Dec | G28: =G$2 -> Jan | H28: =H$2 -> Feb | I28: =I$2 -> Mar | J28: =J$2 -> Apr | K28: =K$2 -> May | L28: =L$2 -> Jun | ... AN28: =AN$2 -> Oct
B29: Capacity | C29: Definitions | D29: % of available demonstrated capacity | E29: =E$3 -> 2022 | F29: =F$3 -> 2022 | G29: =G$3 -> 2023 | H29: =H$3 -> 2023 | I29: =I$3 -> 2023 | J29: =J$3 -> 2023 | K29: =K$3 -> 2023 | L29: =L$3 -> 2023 | ... AN29: =AN$3 -> 2025
B30: Planned available demonstrated capacity | C30: Planned available demonstrated capacity = x% of available demonstrated capacity | D30: 0.8 | E30: =E31*$D30 -> 160000 | F30: =F31*$D30 -> 160000 | G30: =G31*$D30 -> 160000 | H30: =H31*$D30 -> 160000 | I30: =I31*$D30 -> 160000 | J30: =J31*$D30 -> 160000 | K30: =K31*$D30 -> 160000 | L30: =L31*$D30 -> 160000 | ... AN30: =AN31*$D30 -> 160000
B31: Available demonstrated capacity | C31: Available demonstrated capacity = MAC * available units/time | E31: 200000 | F31: 200000 | G31: 200000 | H31: 200000 | I31: 200000 | J31: 200000 | K31: 200000 | L31: 200000 | M31: 200000 | N31: 200000 | O31: 200000 | P31: 200000 | Q31: 200000 | R31: 200000 | S31: 200000 | T31: 200000 | U31: 200000 | V31: 200000 | W31: 200000 | X31: 200000 | Y31: 200000 | Z31: 200000 | AA31: 200000 | AB31: 200000 | AC31: 200000 | AD31: 200000 | AE31: 200000 | AF31: 200000 | AG31: 200000 | AH31: 200000 | AI31: 200000 | AJ31: 200000 | AK31: 200000 | AL31: 200000 | AM31: 200000 | AN31: 200000
B33: Product category | E33: =CONCATENATE(E34,E35) -> Nov2022 | F33: =CONCATENATE(F34,F35) -> Dec2022 | G33: =CONCATENATE(G34,G35) -> Jan2023 | H33: =CONCATENATE(H34,H35) -> Feb2023 | I33: =CONCATENATE(I34,I35) -> Mar2023 | J33: =CONCATENATE(J34,J35) -> Apr2023 | K33: =CONCATENATE(K34,K35) -> May2023 | L33: =CONCATENATE(L34,L35) -> Jun2023 | ... AN33: =CONCATENATE(AN34,AN35) -> Oct2025
B34: Trunk seals | E34: =E$2 -> Nov | F34: =F$2 -> Dec | G34: =G$2 -> Jan | H34: =H$2 -> Feb | I34: =I$2 -> Mar | J34: =J$2 -> Apr | K34: =K$2 -> May | L34: =L$2 -> Jun | ... AN34: =AN$2 -> Oct
B35: Capacity | C35: Definitions | D35: % of available demonstrated capacity | E35: =E$3 -> 2022 | F35: =F$3 -> 2022 | G35: =G$3 -> 2023 | H35: =H$3 -> 2023 | I35: =I$3 -> 2023 | J35: =J$3 -> 2023 | K35: =K$3 -> 2023 | L35: =L$3 -> 2023 | ... AN35: =AN$3 -> 2025
B36: Planned available demonstrated capacity | C36: Planned available demonstrated capacity = x% of available demonstrated capacity | D36: 0.8 | E36: =E37*$D36 -> 32000 | F36: =F37*$D36 -> 32000 | G36: =G37*$D36 -> 32000 | H36: =H37*$D36 -> 32000 | I36: =I37*$D36 -> 32000 | J36: =J37*$D36 -> 32000 | K36: =K37*$D36 -> 32000 | L36: =L37*$D36 -> 32000 | ... AN36: =AN37*$D36 -> 32000
B37: Available demonstrated capacity | C37: Available demonstrated capacity = MAC * available units/time | E37: 40000 | F37: 40000 | G37: 40000 | H37: 40000 | I37: 40000 | J37: 40000 | K37: 40000 | L37: 40000 | M37: 40000 | N37: 40000 | O37: 40000 | P37: 40000 | Q37: 40000 | R37: 40000 | S37: 40000 | T37: 40000 | U37: 40000 | V37: 40000 | W37: 40000 | X37: 40000 | Y37: 40000 | Z37: 40000 | AA37: 40000 | AB37: 40000 | AC37: 40000 | AD37: 40000 | AE37: 40000 | AF37: 40000 | AG37: 40000 | AH37: 40000 | AI37: 40000 | AJ37: 40000 | AK37: 40000 | AL37: 40000 | AM37: 40000 | AN37: 40000
B39: Product category | E39: =CONCATENATE(E40,E41) -> Nov2022 | F39: =CONCATENATE(F40,F41) -> Dec2022 | G39: =CONCATENATE(G40,G41) -> Jan2023 | H39: =CONCATENATE(H40,H41) -> Feb2023 | I39: =CONCATENATE(I40,I41) -> Mar2023 | J39: =CONCATENATE(J40,J41) -> Apr2023 | K39: =CONCATENATE(K40,K41) -> May2023 | L39: =CONCATENATE(L40,L41) -> Jun2023 | ... AN39: =CONCATENATE(AN40,AN41) -> Oct2025
B40: Sun roof seals | E40: =E$2 -> Nov | F40: =F$2 -> Dec | G40: =G$2 -> Jan | H40: =H$2 -> Feb | I40: =I$2 -> Mar | J40: =J$2 -> Apr | K40: =K$2 -> May | L40: =L$2 -> Jun | ... AN40: =AN$2 -> Oct
B41: Capacity | C41: Definitions | D41: % of available demonstrated capacity | E41: =E$3 -> 2022 | F41: =F$3 -> 2022 | G41: =G$3 -> 2023 | H41: =H$3 -> 2023 | I41: =I$3 -> 2023 | J41: =J$3 -> 2023 | K41: =K$3 -> 2023 | L41: =L$3 -> 2023 | ... AN41: =AN$3 -> 2025
B42: Planned available demonstrated capacity | C42: Planned available demonstrated capacity = x% of available demonstrated capacity | D42: 0.8 | E42: =E43*$D42 -> 72000 | F42: =F43*$D42 -> 72000 | G42: =G43*$D42 -> 72000 | H42: =H43*$D42 -> 72000 | I42: =I43*$D42 -> 72000 | J42: =J43*$D42 -> 72000 | K42: =K43*$D42 -> 72000 | L42: =L43*$D42 -> 72000 | ... AN42: =AN43*$D42 -> 72000
B43: Available demonstrated capacity | C43: Available demonstrated capacity = MAC * available units/time | E43: 90000 | F43: 90000 | G43: 90000 | H43: 90000 | I43: 90000 | J43: 90000 | K43: 90000 | L43: 90000 | M43: 90000 | N43: 90000 | O43: 90000 | P43: 90000 | Q43: 90000 | R43: 90000 | S43: 90000 | T43: 90000 | U43: 90000 | V43: 90000 | W43: 90000 | X43: 90000 | Y43: 90000 | Z43: 90000 | AA43: 90000 | AB43: 90000 | AC43: 90000 | AD43: 90000 | AE43: 90000 | AF43: 90000 | AG43: 90000 | AH43: 90000 | AI43: 90000 | AJ43: 90000 | AK43: 90000 | AL43: 90000 | AM43: 90000 | AN43: 90000
B45: Product category | E45: =CONCATENATE(E46,E47) -> Nov2022 | F45: =CONCATENATE(F46,F47) -> Dec2022 | G45: =CONCATENATE(G46,G47) -> Jan2023 | H45: =CONCATENATE(H46,H47) -> Feb2023 | I45: =CONCATENATE(I46,I47) -> Mar2023 | J45: =CONCATENATE(J46,J47) -> Apr2023 | K45: =CONCATENATE(K46,K47) -> May2023 | L45: =CONCATENATE(L46,L47) -> Jun2023 | ... AN45: =CONCATENATE(AN46,AN47) -> Oct2025
B46: Hood to cowl seal / radiator seal | E46: =E$2 -> Nov | F46: =F$2 -> Dec | G46: =G$2 -> Jan | H46: =H$2 -> Feb | I46: =I$2 -> Mar | J46: =J$2 -> Apr | K46: =K$2 -> May | L46: =L$2 -> Jun | ... AN46: =AN$2 -> Oct
B47: Capacity | C47: Definitions | D47: % of available demonstrated capacity | E47: =E$3 -> 2022 | F47: =F$3 -> 2022 | G47: =G$3 -> 2023 | H47: =H$3 -> 2023 | I47: =I$3 -> 2023 | J47: =J$3 -> 2023 | K47: =K$3 -> 2023 | L47: =L$3 -> 2023 | ... AN47: =AN$3 -> 2025
B48: Planned available demonstrated capacity | C48: Planned available demonstrated capacity = x% of available demonstrated capacity | D48: 0.8 | E48: =E49*$D48 -> 88000 | F48: =F49*$D48 -> 88000 | G48: =G49*$D48 -> 88000 | H48: =H49*$D48 -> 88000 | I48: =I49*$D48 -> 88000 | J48: =J49*$D48 -> 88000 | K48: =K49*$D48 -> 88000 | L48: =L49*$D48 -> 88000 | ... AN48: =AN49*$D48 -> 88000
B49: Available demonstrated capacity | C49: Available demonstrated capacity = MAC * available units/time | E49: 110000 | F49: 110000 | G49: 110000 | H49: 110000 | I49: 110000 | J49: 110000 | K49: 110000 | L49: 110000 | M49: 110000 | N49: 110000 | O49: 110000 | P49: 110000 | Q49: 110000 | R49: 110000 | S49: 110000 | T49: 110000 | U49: 110000 | V49: 110000 | W49: 110000 | X49: 110000 | Y49: 110000 | Z49: 110000 | AA49: 110000 | AB49: 110000 | AC49: 110000 | AD49: 110000 | AE49: 110000 | AF49: 110000 | AG49: 110000 | AH49: 110000 | AI49: 110000 | AJ49: 110000 | AK49: 110000 | AL49: 110000 | AM49: 110000 | AN49: 110000
...

Sheet RCCP Extrusion
B2: Please fill current month number and year below
B3: Current Month | C3: 11
B4: Current year | C4: 2022
B6: Extruder-1 | E6: 0 | F6: 1 | G6: 2 | H6: 3 | I6: 4 | J6: 5 | K6: 6 | L6: 7 | M6: 8 | N6: 9 | O6: 10 | P6: 11 | Q6: 12 | R6: 13 | S6: 14 | T6: 15 | U6: 16 | V6: 17 | W6: 18 | X6: 19 | Y6: 20 | Z6: 21 | AA6: 22 | AB6: 23 | AC6: 24 | AD6: 25 | AE6: 26 | AF6: 27 | AG6: 28 | AH6: 29 | AI6: 30 | AJ6: 31 | AK6: 32 | AL6: 33 | AM6: 34 | AN6: 35
B7: Input | C7: Definitions | D7: Standard Markup value | E7: =VLOOKUP(($C$3+E$6),'Dates conversion sheet'!$G:$H,2,0) -> Nov | F7: =VLOOKUP(($C$3+F$6),'Dates conversion sheet'!$G:$H,2,0) -> Dec | G7: =VLOOKUP(($C$3+G$6),'Dates conversion sheet'!$G:$H,2,0) -> Jan | H7: =VLOOKUP(($C$3+H$6),'Dates conversion sheet'!$G:$H,2,0) -> Feb | I7: =VLOOKUP(($C$3+I$6),'Dates conversion sheet'!$G:$H,2,0) -> Mar | J7: =VLOOKUP(($C$3+J$6),'Dates conversion sheet'!$G:$H,2,0) -> Apr | K7: =VLOOKUP(($C$3+K$6),'Dates conversion sheet'!$G:$H,2,0) -> May | L7: =VLOOKUP(($C$3+L$6),'Dates conversion sheet'!$G:$H,2,0) -> Jun | ... AN7: =VLOOKUP(($C$3+AN$6),'Dates conversion sheet'!$G:$H,2,0) -> Oct
E8: =$C$4 -> 2022 | F8: =IF(F$7="Jan",E$8+1,E$8) -> 2022 | G8: =IF(G$7="Jan",F$8+1,F$8) -> 2023 | H8: =IF(H$7="Jan",G$8+1,G$8) -> 2023 | I8: =IF(I$7="Jan",H$8+1,H$8) -> 2023 | J8: =IF(J$7="Jan",I$8+1,I$8) -> 2023 | K8: =IF(K$7="Jan",J$8+1,J$8) -> 2023 | L8: =IF(L$7="Jan",K$8+1,K$8) -> 2023 | M8: =IF(M$7="Jan",L$8+1,L$8) -> 2023 | ... AN8: =IF(AN$7="Jan",AM$8+1,AM$8) -> 2025
B9: Demand Plan (mtr) | C9: Demand Plan as provided by Demand Planning (derived from sheet Demand Plan) | E9: 412062 | F9: 383555 | G9: 387641 | H9: =IFERROR(INDEX('RCCP Conversion'!$B$2:$AL$9999,MATCH('RCCP Extrusion'!$B6,'RCCP Conversion'!$B$2:$B$9999,0),MATCH(CONCATENATE('RCCP Extrusion'!H$8,'RCCP Extrusion'!H$7),'RCCP Conversion'!$B$2:$AL$2,0)),0) -> 0 | I9: =IFERROR(INDEX('RCCP Conversion'!$B$2:$AL$9999,MATCH('RCCP Extrusion'!$B6,'RCCP Conversion'!$B$2:$B$9999,0),MATCH(CONCATENATE('RCCP Extrusion'!I$8,'RCCP Extrusion'!I$7),'RCCP Conversion'!$B$2:$AL$2,0)),0) -> 0 | J9: =IFERROR(INDEX('RCCP Conversion'!$B$2:$AL$9999,MATCH('RCCP Extrusion'!$B6,'RCCP Conversion'!$B$2:$B$9999,0),MATCH(CONCATENATE('RCCP Extrusion'!J$8,'RCCP Extrusion'!J$7),'RCCP Conversion'!$B$2:$AL$2,0)),0) -> 0 | K9: =IFERROR(INDEX('RCCP Conversion'!$B$2:$AL$9999,MATCH('RCCP Extrusion'!$B6,'RCCP Conversion'!$B$2:$B$9999,0),MATCH(CONCATENATE('RCCP Extrusion'!K$8,'RCCP Extrusion'!K$7),'RCCP Conversion'!$B$2:$AL$2,0)),0) -> 0 | L9: =IFERROR(INDEX('RCCP Conversion'!$B$2:$AL$9999,MATCH('RCCP Extrusion'!$B6,'RCCP Conversion'!$B$2:$B$9999,0),MATCH(CONCATENATE('RCCP Extrusion'!L$8,'RCCP Extrusion'!L$7),'RCCP Conversion'!$B$2:$AL$2,0)),0) -> 0 | M9: =IFERROR(INDEX('RCCP Conversion'!$B$2:$AL$9999,MATCH('RCCP Extrusion'!$B6,'RCCP Conversion'!$B$2:$B$9999,0),MATCH(CONCATENATE('RCCP Extrusion'!M$8,'RCCP Extrusion'!M$7),'RCCP Conversion'!$B$2:$AL$2,0)),0) -> 0 | N9: =IFERROR(INDEX('RCCP Conversion'!$B$2:$AL$9999,MATCH('RCCP Extrusion'!$B6,'RCCP Conversion'!$B$2:$B$9999,0),MATCH(CONCATENATE('RCCP Extrusion'!N$8,'RCCP Extrusion'!N$7),'RCCP Conversion'!$B$2:$AL$2,0)),0) -> 0 | O9: =IFERROR(INDEX('RCCP Conversion'!$B$2:$AL$9999,MATCH('RCCP Extrusion'!$B6,'RCCP Conversion'!$B$2:$B$9999,0),MATCH(CONCATENATE('RCCP Extrusion'!O$8,'RCCP Extrusion'!O$7),'RCCP Conversion'!$B$2:$AL$2,0)),0) -> 0 | ... AN9: =IFERROR(INDEX('RCCP Conversion'!$B$2:$AL$9999,MATCH('RCCP Extrusion'!$B6,'RCCP Conversion'!$B$2:$B$9999,0),MATCH(CONCATENATE('RCCP Extrusion'!AN$8,'RCCP Extrusion'!AN$7),'RCCP Conversion'!$B$2:$AL$2,0)),0) -> 0
B10: Demand Plan Total Gross | C10: Demand Plan including intermediate production and MTO demand | E10: =SUM(E9:E9) -> 412062 | F10: =SUM(F9:F9) -> 383555 | G10: =SUM(G9:G9) -> 387641 | H10: =SUM(H9:H9) -> 0 | I10: =SUM(I9:I9) -> 0 | J10: =SUM(J9:J9) -> 0 | K10: =SUM(K9:K9) -> 0 | L10: =SUM(L9:L9) -> 0 | ... AN10: =SUM(AN9:AN9) -> 0
B11: ICD demand plan | C11: Demand for Intercompany Deliveries (ICD) that are currently not in the Demand plan (e.g a stock transfer between two DCs or sites) | D11: 0 | E11: =E9*$D11 -> 0 | F11: =F9*$D11 -> 0 | G11: =G9*$D11 -> 0 | H11: =H9*$D11 -> 0 | I11: =I9*$D11 -> 0 | J11: =J9*$D11 -> 0 | K11: =K9*$D11 -> 0 | L11: =L9*$D11 -> 0 | ... AN11: =AN9*$D11 -> 0
B12: Demand Plan Total Net | C12: Sum of Demand Plan including intermediates, MTO and ICD demand | E12: =SUM(E9:E9,E11,E13:E13) -> 413062 | F12: =SUM(F9:F9,F11,F13:F13) -> 383555 | G12: =SUM(G9:G9,G11,G13:G13) -> 387641 | H12: =SUM(H9:H9,H11,H13:H13) -> 0 | I12: =SUM(I9:I9,I11,I13:I13) -> 0 | J12: =SUM(J9:J9,J11,J13:J13) -> 0 | K12: =SUM(K9:K9,K11,K13:K13) -> 0 | L12: =SUM(L9:L9,L11,L13:L13) -> 0 | ... AN12: =SUM(AN9:AN9,AN11,AN13:AN13) -> 0
B13: NPI Volume | C13: New Product Introduction (NPI) is volume that is expected to be produced by the site in the future but not included in the demand plan yet. The application of this field is to see if the site will be capable to take the extra volume given its capability | E13: 1000
B14: Gap Closing actions (increasing volume) | C14: All agreed & proposed actions to close gaps by INCREASING volume in a given month that impact the to be produced volume can be entered here | E14: 0 | F14: 0 | G14: 0
B15: Gap Closing actions (decreasing volume) | C15: All agreed & proposed actions to close gaps by DECREASING volume in a given month that impact the to be produced volume can be entered here | E15: 0 | F15: 0 | G15: 0
B16: Final volume based on Demand Plan including Gap Closing actions | C16: Final to be produced volume based on Total Net Demand Plan including gap closing actions | E16: =E12+E14-E15 -> 413062 | F16: =F12+F14-F15 -> 383555 | G16: =G12+G14-G15 -> 387641 | H16: =H12+H14-H15 -> 0 | I16: =I12+I14-I15 -> 0 | J16: =J12+J14-J15 -> 0 | K16: =K12+K14-K15 -> 0 | L16: =L12+L14-L15 -> 0 | ... AN16: =AN12+AN14-AN15 -> 0
B17: Planned available demonstrated capacity | C17: Planned available demonstrated capacity = x% of available demonstrated capacity | E17: 532663.94 | F17: 532663.94 | G17: 532663.94
B18: Planned available demonstrated capacity Utilization | C18: Total net Demand plan divided by Planned available demonstrated capacity | E18: =E16/E17 -> 0.77546455 | F18: =F16/F17 -> 0.7200694 | G18: =G16/G17 -> 0.72774028 | H18: =H16/H17 -> #DIV/0!
B19: Available demonstrated capacity | C19: Available demonstrated capacity = MAC * available units/time | E19: =E17 -> 532663.94 | F19: =F17 -> 532663.94 | G19: =G17 -> 532663.94 | H19: =H17 -> 0
B20: Capacity Utilization Available Demonstrated capacity (%) | C20: Total net demand plan divided by Available Demonstrated capacity | E20: =E16/E19 -> 0.77546455 | F20: =F16/F19 -> 0.7200694 | G20: =G16/G19 -> 0.72774028 | H20: =H16/H19 -> #DIV/0!
B21: Actual Efficiency (%)
B22: Graph simulation | C22: For graph purpose only | E22: =SUM(E12,-E15) -> 413062 | F22: =SUM(F12,-F15) -> 383555 | G22: =SUM(G12,-G15) -> 387641 | H22: =SUM(H12,-H15) -> 0 | I22: =SUM(I12,-I15) -> 0 | J22: =SUM(J12,-J15) -> 0 | K22: =SUM(K12,-K15) -> 0 | L22: =SUM(L12,-L15) -> 0 | ... AN22: =SUM(AN12,-AN15) -> 0
B24: Extruder-2 | E24: 0 | F24: 1 | G24: 2 | H24: 3 | I24: 4 | J24: 5 | K24: 6 | L24: 7 | M24: 8 | N24: 9 | O24: 10 | P24: 11 | Q24: 12 | R24: 13 | S24: 14 | T24: 15 | U24: 16 | V24: 17 | W24: 18 | X24: 19 | Y24: 20 | Z24: 21 | AA24: 22 | AB24: 23 | AC24: 24 | AD24: 25 | AE24: 26 | AF24: 27 | AG24: 28 | AH24: 29 | AI24: 30 | AJ24: 31 | AK24: 32 | AL24: 33 | AM24: 34 | AN24: 35
B25: Input | C25: Definitions | D25: Standard Markup value | E25: =VLOOKUP(($C$3+E$6),'Dates conversion sheet'!$G:$H,2,0) -> Nov | F25: =VLOOKUP(($C$3+F$6),'Dates conversion sheet'!$G:$H,2,0) -> Dec | G25: =VLOOKUP(($C$3+G$6),'Dates conversion sheet'!$G:$H,2,0) -> Jan | H25: =VLOOKUP(($C$3+H$6),'Dates conversion sheet'!$G:$H,2,0) -> Feb | I25: =VLOOKUP(($C$3+I$6),'Dates conversion sheet'!$G:$H,2,0) -> Mar | J25: =VLOOKUP(($C$3+J$6),'Dates conversion sheet'!$G:$H,2,0) -> Apr | K25: =VLOOKUP(($C$3+K$6),'Dates conversion sheet'!$G:$H,2,0) -> May | L25: =VLOOKUP(($C$3+L$6),'Dates conversion sheet'!$G:$H,2,0) -> Jun | ... AN25: =VLOOKUP(($C$3+AN$6),'Dates conversion sheet'!$G:$H,2,0) -> Oct
E26: =$C$4 -> 2022 | F26: =IF(F$7="Jan",E$8+1,E$8) -> 2022 | G26: =IF(G$7="Jan",F$8+1,F$8) -> 2023 | H26: =IF(H$7="Jan",G$8+1,G$8) -> 2023 | I26: =IF(I$7="Jan",H$8+1,H$8) -> 2023 | J26: =IF(J$7="Jan",I$8+1,I$8) -> 2023 | K26: =IF(K$7="Jan",J$8+1,J$8) -> 2023 | L26: =IF(L$7="Jan",K$8+1,K$8) -> 2023 | M26: =IF(M$7="Jan",L$8+1,L$8) -> 2023 | ... AN26: =IF(AN$7="Jan",AM$8+1,AM$8) -> 2025
